Workbook

Sheet Cara pakai
A1: Parafrase teks tampilan EDUNEXA → Sigrak
A2: Disusun 29 Oktober 2026 dari halaman publik portal-edunexa.web.app dan skrip dialog/notifikasinya. Tidak ada data guru atau siswa yang diambil atau disimpan.
A4: Tab Parafrase: satu baris per teks. Kolom Teks baru dan Catatan boleh diedit langsung; kolom Status terisi otomatis (Tetap bila teks lama = teks baru).
A5: Tab Istilah: daftar istilah baku. Pakai daftar ini saat menulis teks baru agar konsisten.
A6: Tab Ringkasan: jumlah teks per halaman, dihitung otomatis dari tab Parafrase.
A8: Tanda {…} = bagian yang diisi program (nama, tanggal, angka, pesan galat teknis). Jangan dihapus saat menerapkan.
A9: Halaman "Semua halaman" = teks yang muncul di beberapa halaman; cukup diganti sekali di komponen bersama.
A10: "Sigrak" adalah nama kerja; bila nama lain dipilih, cari-ganti "Sigrak".
A11: Teks (baru) = elemen baru dari perombakan fitur, belum ada di versi sekarang.
A13: Contoh baris (format yang diharapkan):
A14: Generator RPM | Tombol | GENERATE MODUL | Buat RPM | Tombol utama, bukan huruf kapital semua

Sheet Parafrase
A1: No | B1: Halaman | C1: Jenis teks | D1: Teks lama | E1: Teks baru | F1: Catatan | G1: Status | H1: Sumber
A2: 1 | B2: Semua halaman | C2: Tombol | D2: Simpan | E2: Simpan | F2: Tetap; bila memungkinkan sebut bendanya: Simpan jurnal, Simpan RPM | G2: =IF(EXACT(D2,E2),"Tetap","Diubah") -> Tetap | H2: Halaman publik
A3: 2 | B3: Semua halaman | C3: Tombol | D3: Download | E3: Unduh | F3: Istilah baku: Unduh | G3: =IF(EXACT(D3,E3),"Tetap","Diubah") -> Diubah | H3: Halaman publik
A4: 3 | B4: Semua halaman | C4: Tombol | D4: Cetak | E4: Cetak | F4: Tetap | G4: =IF(EXACT(D4,E4),"Tetap","Diubah") -> Tetap | H4: Halaman publik
A5: 4 | B5: Semua halaman | C5: Tombol | D5: Kembali | E5: Kembali | F5: Tetap | G5: =IF(EXACT(D5,E5),"Tetap","Diubah") -> Tetap | H5: Halaman publik
A6: 5 | B6: Semua halaman | C6: Tombol | D6: Edit | E6: Ubah | F6: Istilah baku: Ubah | G6: =IF(EXACT(D6,E6),"Tetap","Diubah") -> Diubah | H6: Halaman publik
A7: 6 | B7: Semua halaman | C7: Tombol | D7: Tambah | E7: Tambah | F7: Tetap; sebut bendanya bila ruang cukup: Tambah siswa | G7: =IF(EXACT(D7,E7),"Tetap","Diubah") -> Tetap | H7: Halaman publik
A8: 7 | B8: Semua halaman | C8: Tombol | D8: Muat Ulang | E8: Muat ulang | F8: Huruf kapital hanya di awal | G8: =IF(EXACT(D8,E8),"Tetap","Diubah") -> Diubah | H8: Halaman publik
A9: 8 | B9: Semua halaman | C9: Tombol | D9: Pilih Semua | E9: Pilih semua | G9: =IF(EXACT(D9,E9),"Tetap","Diubah") -> Diubah | H9: Halaman publik
A10: 9 | B10: Semua halaman | C10: Tombol | D10: Coba Lagi | E10: Coba lagi | G10: =IF(EXACT(D10,E10),"Tetap","Diubah") -> Diubah | H10: Halaman publik
A11: 10 | B11: Semua halaman | C11: Tombol | D11: Keluar & Login Ulang | E11: Masuk ulang | F11: Satu tindakan, satu kata kerja | G11: =IF(EXACT(D11,E11),"Tetap","Diubah") -> Diubah | H11: Halaman publik
A12: 11 | B12: Semua halaman | C12: Status proses | D12: Memuat... | E12: Memuat… | F12: Pakai elipsis satu karakter | G12: =IF(EXACT(D12,E12),"Tetap","Diubah") -> Diubah | H12: Halaman publik
A13: 12 | B13: Semua halaman | C13: Status proses | D13: Memuat Data... | E13: Memuat data… | G13: =IF(EXACT(D13,E13),"Tetap","Diubah") -> Diubah | H13: Halaman publik
A14: 13 | B14: Semua halaman | C14: Status proses | D14: Memuat data... | E14: Memuat data… | G14: =IF(EXACT(D14,E14),"Tetap","Diubah") -> Diubah | H14: Halaman publik
A15: 14 | B15: Semua halaman | C15: Status proses | D15: Mendeteksi dari Portal... | E15: Membaca kelas aktif… | G15: =IF(EXACT(D15,E15),"Tetap","Diubah") -> Diubah | H15: Halaman publik
A16: 15 | B16: Semua halaman | C16: Label formulir | D16: Target Kelas & Semester (Auto-Sync) | E16: Kelas dan semester | F16: "Auto-Sync" dihapus; tambah keterangan kecil "diambil dari kelas aktif" | G16: =IF(EXACT(D16,E16),"Tetap","Diubah") -> Diubah | H16: Halaman publik
A17: 16 | B17: Semua halaman | C17: Label formulir | D17: Semua Mata Pelajaran | E17: Semua mata pelajaran | G17: =IF(EXACT(D17,E17),"Tetap","Diubah") -> Diubah | H17: Halaman publik
A18: 17 | B18: Semua halaman | C18: Judul kolom | D18: Aksi | E18: Aksi | F18: Tetap; di HP diganti ikon titik tiga dengan label aksesibel | G18: =IF(EXACT(D18,E18),"Tetap","Diubah") -> Tetap | H18: Halaman publik
A19: 18 | B19: Semua halaman | C19: Judul kolom | D19: Aksi Penanganan | E19: Aksi | G19: =IF(EXACT(D19,E19),"Tetap","Diubah") -> Diubah | H19: Halaman publik
A20: 19 | B20: Semua halaman | C20: Judul kolom | D20: No | E20: No. | G20: =IF(EXACT(D20,E20),"Tetap","Diubah") -> Diubah | H20: Halaman publik
A21: 20 | B21: Semua halaman | C21: Judul kolom | D21: Judul Dokumen | E21: Judul | G21: =IF(EXACT(D21,E21),"Tetap","Diubah") -> Diubah | H21: Halaman publik
A22: 21 | B22: Semua halaman | C22: Judul kolom | D22: Tanggal Buat | E22: Dibuat | G22: =IF(EXACT(D22,E22),"Tetap","Diubah") -> Diubah | H22: Halaman publik
A23: 22 | B23: Semua halaman | C23: Label formulir | D23: Tanggal Pelaksanaan | E23: Tanggal pelaksanaan | G23: =IF(EXACT(D23,E23),"Tetap","Diubah") -> Diubah | H23: Halaman publik
A24: 23 | B24: Semua halaman | C24: Pesan kosong | D24: Sistem Edunexa Siap. | E24: Pratinjau akan muncul di sini. | F24: Pesan kosong menjelaskan apa yang akan tampil | G24: =IF(EXACT(D24,E24),"Tetap","Diubah") -> Diubah | H24: Halaman publik
A25: 24 | B25: Semua halaman | C25: Tombol | D25: Simpan Lokal | E25: Simpan | F25: Penyimpanan ke server; tidak perlu membedakan lokal | G25: =IF(EXACT(D25,E25),"Tetap","Diubah") -> Diubah | H25: Halaman publik
A26: 25 | B26: Semua halaman | C26: Tombol | D26: Word | E26: Unduh Word | G26: =IF(EXACT(D26,E26),"Tetap","Diubah") -> Diubah | H26: Halaman publik
A27: 26 | B27: Semua halaman | C27: Tombol | D27: DOCX | E27: Unduh Word | F27: Pengguna mengenal "Word", bukan DOCX | G27: =IF(EXACT(D27,E27),"Tetap","Diubah") -> Diubah | H27: Halaman publik
A28: 27 | B28: Semua halaman | C28: Tombol | D28: PDF | E28: Unduh PDF | G28: =IF(EXACT(D28,E28),"Tetap","Diubah") -> Diubah | H28: Halaman publik
A29: 28 | B29: Semua halaman | C29: Tombol | D29: Download PDF | E29: Unduh PDF | G29: =IF(EXACT(D29,E29),"Tetap","Diubah") -> Diubah | H29: Halaman publik
A30: 29 | B30: Semua halaman | C30: Tombol | D30: Download Cadangan | E30: Ekspor data | F30: Dipindah ke Akun > Ekspor data | G30: =IF(EXACT(D30,E30),"Tetap","Diubah") -> Diubah | H30: Halaman publik
A31: 30 | B31: Semua halaman | C31: Tombol | D31: Impor Cadangan | E31: Pulihkan dari file | F31: Dipindah ke Akun | G31: =IF(EXACT(D31,E31),"Tetap","Diubah") -> Diubah | H31: Halaman publik
A32: 31 | B32: Semua halaman | C32: Pilihan | D32: Ganjil (1) | E32: Semester 1 (Ganjil) | F32: Angka di depan agar urut | G32: =IF(EXACT(D32,E32),"Tetap","Diubah") -> Diubah | H32: Halaman publik
A33: 32 | B33: Semua halaman | C33: Pilihan | D33: Genap (2) | E33: Semester 2 (Genap) | G33: =IF(EXACT(D33,E33),"Tetap","Diubah") -> Diubah | H33: Halaman publik
A34: 33 | B34: Semua halaman | C34: Kontrol | D34: − 100% + | E34: Perkecil / 100% / Perbesar | F34: Ikon tetap, beri label aksesibel | G34: =IF(EXACT(D34,E34),"Tetap","Diubah") -> Diubah | H34: Halaman publik
A35: 34 | B35: Semua halaman | C35: Placeholder | D35: -- Pilih Mapel Terlebih Dahulu -- | E35: Pilih mata pelajaran dulu | G35: =IF(EXACT(D35,E35),"Tetap","Diubah") -> Diubah | H35: Halaman publik
A36: 35 | B36: Semua halaman | C36: Placeholder | D36: -- Pilih Tanggal Terlebih Dahulu -- | E36: Pilih tanggal dulu | G36: =IF(EXACT(D36,E36),"Tetap","Diubah") -> Diubah | H36: Halaman publik
A37: 36 | B37: Semua halaman | C37: Label formulir | D37: Jenjang | E37: Jenjang | F37: Sementara hanya SD/MI; pilihan lain disembunyikan | G37: =IF(EXACT(D37,E37),"Tetap","Diubah") -> Tetap | H37: Halaman publik
A38: 37 | B38: Semua halaman | C38: Pilihan | D38: SMP/MTs, SMA/MA, SMK/MAK | E38: (disembunyikan) | F38: Tampil lagi saat data jenjang tersebut siap | G38: =IF(EXACT(D38,E38),"Tetap","Diubah") -> Diubah | H38: Halaman publik
A39: 38 | B39: Semua halaman | C39: Pilihan | D39: Kelas 7 sampai Kelas 12 | E39: (disembunyikan) | F39: Data materi baru ada untuk kelas 1–6 | G39: =IF(EXACT(D39,E39),"Tetap","Diubah") -> Diubah | H39: Halaman publik
A40: 39 | B40: Semua halaman | C40: Judul menu | D40: Pengaturan Portal | E40: Akun | G40: =IF(EXACT(D40,E40),"Tetap","Diubah") -> Diubah | H40: Halaman publik
...

Sheet Istilah
A1: Istilah lama | B1: Istilah baku | C1: Catatan
A2: Download | B2: Unduh | C2: Tombol dan pesan
A3: Generate / GENERATE MODUL | B3: Buat (Buat RPM, Buat soal, Buat LKPD) | C3: Kata kerja yang dipakai guru
A4: Modul Ajar / Modul | B4: RPM | C4: Satu nama untuk dokumen perencanaan
A5: Modul mandiri / Mode Manual | B5: RPM lepas jadwal
A6: Bank Modul / Arsip / Penyimpanan Lokal | B6: Dokumen Saya | C6: Satu tempat semua dokumen
A7: Worksheet | B7: LKPD | C7: Istilah resmi kurikulum
A8: Bank Soal (menu) | B8: Buat Soal (di menu Asesmen) | C8: Penyimpanan soal tetap di Dokumen Saya
A9: Penilaian (menu) | B9: Asesmen
A10: Administrasi Kelas | B10: Kelas Saya (+ Di Kelas untuk absensi, jurnal, catatan)
A11: Pemberitahuan / Papan informasi siaran | B11: Kabar | C11: Dari sekolah ke guru
A12: Pemberitahuan (kepala sekolah ke guru) | B12: Pengingat
A13: Tutorial | B13: Bantuan
A14: Pengaturan / Pengaturan Portal | B14: Akun (pribadi) / Pengaturan Sekolah (sekolah)
A15: Dashboard / Dasbord | B15: Ringkasan (portal) / Hari Ini (guru)
A16: API Key / API Key Gemini | B16: Kunci AI
A17: Password | B17: Kata sandi
A18: Username | B18: Nama pengguna
A19: Login / Masuk Portal | B19: Masuk
A20: Instansi | B20: Sekolah
A21: Super Admin (untuk guru) | B21: Tim Sigrak / admin sekolah | C21: Sesuai siapa yang benar-benar memutuskan
A22: Role / Hak Akses | B22: Peran
A23: Cloud / Firestore / Firebase / sinkronisasi | B23: server / tersimpan di akun | C23: Nama teknologi tidak ditampilkan
A24: Edit | B24: Ubah
A25: Reset | B25: Kembalikan / Atur ulang
A26: Timpa | B26: Ganti
A27: Presensi / Kehadiran / Daftar Hadir | B27: Absensi
A28: Mapel (di kalimat) | B28: Mata pelajaran | C28: Singkatan boleh di label sempit: guru mapel
A29: Mutasi siswa | B29: Pindah dan keluar
A30: Master EDUNEXA | B30: Kurikulum bawaan
A31: Ijin | B31: Izin | C31: Ejaan baku
A32: Gagal … | B32: … belum berhasil | C32: Lebih tenang; tetap jelas
A33: Ya, Hapus / Ya, Timpa | B33: Hapus [benda] / Ganti | C33: Tombol menyebut tindakan
A34: Huruf kapital semua (GENERATE, UPDATE TERSEDIA) | B34: Huruf kapital di awal saja
A35: Tanda seru (!) | B35: Titik
A36: Emoji (✅ ❌ 🎉) | B36: Tanpa emoji
A37: ... | B37: … | C37: Elipsis satu karakter
A38: & | B38: dan | C38: Di teks tampilan

Sheet Ringkasan
A1: Halaman | B1: Jumlah teks | C1: Diubah | D1: Tetap | E1: Galat dan galat formulir | F1: Konfirmasi | G1: Pesan kosong
A2: Semua halaman | B2: =COUNTIFS(Parafrase!$B:$B,A2) -> 70 | C2: =COUNTIFS(Parafrase!$B:$B,A2,Parafrase!$G:$G,"Diubah") -> 57 | D2: =COUNTIFS(Parafrase!$B:$B,A2,Parafrase!$G:$G,"Tetap") -> 13 | E2: =COUNTIFS(Parafrase!$B:$B,A2,Parafrase!$C:$C,"Galat*") -> 4 | F2: =COUNTIFS(Parafrase!$B:$B,A2,Parafrase!$C:$C,"Konfirmasi") -> 0 | G2: =COUNTIFS(Parafrase!$B:$B,A2,Parafrase!$C:$C,"Pesan kosong") -> 1
A3: Beranda & akun (index.html) | B3: =COUNTIFS(Parafrase!$B:$B,A3) -> 272 | C3: =COUNTIFS(Parafrase!$B:$B,A3,Parafrase!$G:$G,"Diubah") -> 254 | D3: =COUNTIFS(Parafrase!$B:$B,A3,Parafrase!$G:$G,"Tetap") -> 18 | E3: =COUNTIFS(Parafrase!$B:$B,A3,Parafrase!$C:$C,"Galat*") -> 67 | F3: =COUNTIFS(Parafrase!$B:$B,A3,Parafrase!$C:$C,"Konfirmasi") -> 10 | G3: =COUNTIFS(Parafrase!$B:$B,A3,Parafrase!$C:$C,"Pesan kosong") -> 3
A4: Generator RPM | B4: =COUNTIFS(Parafrase!$B:$B,A4) -> 112 | C4: =COUNTIFS(Parafrase!$B:$B,A4,Parafrase!$G:$G,"Diubah") -> 106 | D4: =COUNTIFS(Parafrase!$B:$B,A4,Parafrase!$G:$G,"Tetap") -> 6 | E4: =COUNTIFS(Parafrase!$B:$B,A4,Parafrase!$C:$C,"Galat*") -> 38 | F4: =COUNTIFS(Parafrase!$B:$B,A4,Parafrase!$C:$C,"Konfirmasi") -> 7 | G4: =COUNTIFS(Parafrase!$B:$B,A4,Parafrase!$C:$C,"Pesan kosong") -> 1
A5: Bank Soal | B5: =COUNTIFS(Parafrase!$B:$B,A5) -> 58 | C5: =COUNTIFS(Parafrase!$B:$B,A5,Parafrase!$G:$G,"Diubah") -> 55 | D5: =COUNTIFS(Parafrase!$B:$B,A5,Parafrase!$G:$G,"Tetap") -> 3 | E5: =COUNTIFS(Parafrase!$B:$B,A5,Parafrase!$C:$C,"Galat*") -> 10 | F5: =COUNTIFS(Parafrase!$B:$B,A5,Parafrase!$C:$C,"Konfirmasi") -> 1 | G5: =COUNTIFS(Parafrase!$B:$B,A5,Parafrase!$C:$C,"Pesan kosong") -> 1
A6: Worksheet/LKPD | B6: =COUNTIFS(Parafrase!$B:$B,A6) -> 27 | C6: =COUNTIFS(Parafrase!$B:$B,A6,Parafrase!$G:$G,"Diubah") -> 27 | D6: =COUNTIFS(Parafrase!$B:$B,A6,Parafrase!$G:$G,"Tetap") -> 0 | E6: =COUNTIFS(Parafrase!$B:$B,A6,Parafrase!$C:$C,"Galat*") -> 7 | F6: =COUNTIFS(Parafrase!$B:$B,A6,Parafrase!$C:$C,"Konfirmasi") -> 1 | G6: =COUNTIFS(Parafrase!$B:$B,A6,Parafrase!$C:$C,"Pesan kosong") -> 1
A7: Administrasi Kelas | B7: =COUNTIFS(Parafrase!$B:$B,A7) -> 608 | C7: =COUNTIFS(Parafrase!$B:$B,A7,Parafrase!$G:$G,"Diubah") -> 529 | D7: =COUNTIFS(Parafrase!$B:$B,A7,Parafrase!$G:$G,"Tetap") -> 79 | E7: =COUNTIFS(Parafrase!$B:$B,A7,Parafrase!$C:$C,"Galat*") -> 79 | F7: =COUNTIFS(Parafrase!$B:$B,A7,Parafrase!$C:$C,"Konfirmasi") -> 29 | G7: =COUNTIFS(Parafrase!$B:$B,A7,Parafrase!$C:$C,"Pesan kosong") -> 12
A8: Portal Kepala Sekolah | B8: =COUNTIFS(Parafrase!$B:$B,A8) -> 199 | C8: =COUNTIFS(Parafrase!$B:$B,A8,Parafrase!$G:$G,"Diubah") -> 180 | D8: =COUNTIFS(Parafrase!$B:$B,A8,Parafrase!$G:$G,"Tetap") -> 19 | E8: =COUNTIFS(Parafrase!$B:$B,A8,Parafrase!$C:$C,"Galat*") -> 55 | F8: =COUNTIFS(Parafrase!$B:$B,A8,Parafrase!$C:$C,"Konfirmasi") -> 5 | G8: =COUNTIFS(Parafrase!$B:$B,A8,Parafrase!$C:$C,"Pesan kosong") -> 2
A9: Portal Pengawas | B9: =COUNTIFS(Parafrase!$B:$B,A9) -> 26 | C9: =COUNTIFS(Parafrase!$B:$B,A9,Parafrase!$G:$G,"Diubah") -> 22 | D9: =COUNTIFS(Parafrase!$B:$B,A9,Parafrase!$G:$G,"Tetap") -> 4 | E9: =COUNTIFS(Parafrase!$B:$B,A9,Parafrase!$C:$C,"Galat*") -> 1 | F9: =COUNTIFS(Parafrase!$B:$B,A9,Parafrase!$C:$C,"Konfirmasi") -> 0 | G9: =COUNTIFS(Parafrase!$B:$B,A9,Parafrase!$C:$C,"Pesan kosong") -> 2
A10: Super Admin (index.html) | B10: =COUNTIFS(Parafrase!$B:$B,A10) -> 65 | C10: =COUNTIFS(Parafrase!$B:$B,A10,Parafrase!$G:$G,"Diubah") -> 61 | D10: =COUNTIFS(Parafrase!$B:$B,A10,Parafrase!$G:$G,"Tetap") -> 4 | E10: =COUNTIFS(Parafrase!$B:$B,A10,Parafrase!$C:$C,"Galat*") -> 0 | F10: =COUNTIFS(Parafrase!$B:$B,A10,Parafrase!$C:$C,"Konfirmasi") -> 0 | G10: =COUNTIFS(Parafrase!$B:$B,A10,Parafrase!$C:$C,"Pesan kosong") -> 2
A11: Tutorial | B11: =COUNTIFS(Parafrase!$B:$B,A11) -> 62 | C11: =COUNTIFS(Parafrase!$B:$B,A11,Parafrase!$G:$G,"Diubah") -> 61 | D11: =COUNTIFS(Parafrase!$B:$B,A11,Parafrase!$G:$G,"Tetap") -> 1 | E11: =COUNTIFS(Parafrase!$B:$B,A11,Parafrase!$C:$C,"Galat*") -> 0 | F11: =COUNTIFS(Parafrase!$B:$B,A11,Parafrase!$C:$C,"Konfirmasi") -> 0 | G11: =COUNTIFS(Parafrase!$B:$B,A11,Parafrase!$C:$C,"Pesan kosong") -> 0
A12: Total | B12: =SUM(B2:B11) -> 1499 | C12: =SUM(C2:C11) -> 1352 | D12: =SUM(D2:D11) -> 147 | E12: =SUM(E2:E11) -> 261 | F12: =SUM(F2:F11) -> 53 | G12: =SUM(G2:G11) -> 25
